[2023-03-20T16:14:44.276+0000] {taskinstance.py:1084} INFO - Dependencies all met for dep_context=non-requeueable deps ti=<TaskInstance: dag_with_minio_s3_v01.sensor_minio_s3 scheduled__2022-02-20T00:00:00+00:00 [queued]>
[2023-03-20T16:14:44.307+0000] {taskinstance.py:1084} INFO - Dependencies all met for dep_context=requeueable deps ti=<TaskInstance: dag_with_minio_s3_v01.sensor_minio_s3 scheduled__2022-02-20T00:00:00+00:00 [queued]>
[2023-03-20T16:14:44.308+0000] {taskinstance.py:1282} INFO - 
--------------------------------------------------------------------------------
[2023-03-20T16:14:44.309+0000] {taskinstance.py:1283} INFO - Starting attempt 2 of 6
[2023-03-20T16:14:44.310+0000] {taskinstance.py:1284} INFO - 
--------------------------------------------------------------------------------
[2023-03-20T16:14:44.379+0000] {taskinstance.py:1303} INFO - Executing <Task(S3KeySensor): sensor_minio_s3> on 2022-02-20 00:00:00+00:00
[2023-03-20T16:14:44.392+0000] {standard_task_runner.py:55} INFO - Started process 1624 to run task
[2023-03-20T16:14:44.407+0000] {standard_task_runner.py:82} INFO - Running: ['***', 'tasks', 'run', 'dag_with_minio_s3_v01', 'sensor_minio_s3', 'scheduled__2022-02-20T00:00:00+00:00', '--job-id', '109', '--raw', '--subdir', 'DAGS_FOLDER/dag_with_minio_s3.py', '--cfg-path', '/tmp/tmpvk4ek0c6']
[2023-03-20T16:14:44.413+0000] {standard_task_runner.py:83} INFO - Job 109: Subtask sensor_minio_s3
[2023-03-20T16:14:44.674+0000] {task_command.py:388} INFO - Running <TaskInstance: dag_with_minio_s3_v01.sensor_minio_s3 scheduled__2022-02-20T00:00:00+00:00 [running]> on host a1e5df821a6d
[2023-03-20T16:14:44.898+0000] {taskinstance.py:1511} INFO - Exporting the following env vars:
AIRFLOW_CTX_DAG_OWNER=ThinhHuynh
AIRFLOW_CTX_DAG_ID=dag_with_minio_s3_v01
AIRFLOW_CTX_TASK_ID=sensor_minio_s3
AIRFLOW_CTX_EXECUTION_DATE=2022-02-20T00:00:00+00:00
AIRFLOW_CTX_TRY_NUMBER=2
AIRFLOW_CTX_DAG_RUN_ID=scheduled__2022-02-20T00:00:00+00:00
[2023-03-20T16:14:44.899+0000] {s3.py:99} INFO - Poking for key : s3://***/data.csv
[2023-03-20T16:14:44.902+0000] {base_aws.py:133} INFO - No connection ID provided. Fallback on boto3 credential strategy (region_name=None). See: https://boto3.amazonaws.com/v1/documentation/api/latest/guide/configuration.html
[2023-03-20T16:14:57.801+0000] {taskinstance.py:1775} ERROR - Task failed with exception
Traceback (most recent call last):
  File "/home/airflow/.local/lib/python3.7/site-packages/airflow/sensors/base.py", line 199, in execute
    poke_return = self.poke(context)
  File "/home/airflow/.local/lib/python3.7/site-packages/airflow/providers/amazon/aws/sensors/s3.py", line 130, in poke
    return self._check_key(self.bucket_key)
  File "/home/airflow/.local/lib/python3.7/site-packages/airflow/providers/amazon/aws/sensors/s3.py", line 118, in _check_key
    obj = self.hook.head_object(key, bucket_name)
  File "/home/airflow/.local/lib/python3.7/site-packages/airflow/providers/amazon/aws/hooks/s3.py", line 111, in wrapper
    return func(*bound_args.args, **bound_args.kwargs)
  File "/home/airflow/.local/lib/python3.7/site-packages/airflow/providers/amazon/aws/hooks/s3.py", line 82, in wrapper
    return func(*bound_args.args, **bound_args.kwargs)
  File "/home/airflow/.local/lib/python3.7/site-packages/airflow/providers/amazon/aws/hooks/s3.py", line 499, in head_object
    return self.get_conn().head_object(Bucket=bucket_name, Key=key)
  File "/home/airflow/.local/lib/python3.7/site-packages/botocore/client.py", line 530, in _api_call
    return self._make_api_call(operation_name, kwargs)
  File "/home/airflow/.local/lib/python3.7/site-packages/botocore/client.py", line 944, in _make_api_call
    operation_model, request_dict, request_context
  File "/home/airflow/.local/lib/python3.7/site-packages/botocore/client.py", line 966, in _make_request
    return self._endpoint.make_request(operation_model, request_dict)
  File "/home/airflow/.local/lib/python3.7/site-packages/botocore/endpoint.py", line 119, in make_request
    return self._send_request(request_dict, operation_model)
  File "/home/airflow/.local/lib/python3.7/site-packages/botocore/endpoint.py", line 198, in _send_request
    request = self.create_request(request_dict, operation_model)
  File "/home/airflow/.local/lib/python3.7/site-packages/botocore/endpoint.py", line 137, in create_request
    operation_name=operation_model.name,
  File "/home/airflow/.local/lib/python3.7/site-packages/botocore/hooks.py", line 412, in emit
    return self._emitter.emit(aliased_event_name, **kwargs)
  File "/home/airflow/.local/lib/python3.7/site-packages/botocore/hooks.py", line 256, in emit
    return self._emit(event_name, kwargs)
  File "/home/airflow/.local/lib/python3.7/site-packages/botocore/hooks.py", line 239, in _emit
    response = handler(**kwargs)
  File "/home/airflow/.local/lib/python3.7/site-packages/botocore/signers.py", line 105, in handler
    return self.sign(operation_name, request)
  File "/home/airflow/.local/lib/python3.7/site-packages/botocore/signers.py", line 189, in sign
    auth.add_auth(request)
  File "/home/airflow/.local/lib/python3.7/site-packages/botocore/auth.py", line 418, in add_auth
    raise NoCredentialsError()
botocore.exceptions.NoCredentialsError: Unable to locate credentials
[2023-03-20T16:14:58.216+0000] {taskinstance.py:1326} INFO - Marking task as UP_FOR_RETRY. dag_id=dag_with_minio_s3_v01, task_id=sensor_minio_s3, execution_date=20220220T000000, start_date=20230320T161444, end_date=20230320T161458
[2023-03-20T16:14:59.003+0000] {standard_task_runner.py:105} ERROR - Failed to execute job 109 for task sensor_minio_s3 (Unable to locate credentials; 1624)
[2023-03-20T16:14:59.065+0000] {local_task_job.py:212} INFO - Task exited with return code 1
[2023-03-20T16:14:59.132+0000] {taskinstance.py:2585} INFO - 0 downstream tasks scheduled from follow-on schedule check
