[2023-03-27T02:09:35.067+0000] {taskinstance.py:1084} INFO - Dependencies all met for dep_context=non-requeueable deps ti=<TaskInstance: dag_with_google_sheet_v01.get_data_from_google_sheet manual__2023-03-27T02:09:32.849106+00:00 [queued]>
[2023-03-27T02:09:35.082+0000] {taskinstance.py:1084} INFO - Dependencies all met for dep_context=requeueable deps ti=<TaskInstance: dag_with_google_sheet_v01.get_data_from_google_sheet manual__2023-03-27T02:09:32.849106+00:00 [queued]>
[2023-03-27T02:09:35.082+0000] {taskinstance.py:1282} INFO - 
--------------------------------------------------------------------------------
[2023-03-27T02:09:35.083+0000] {taskinstance.py:1283} INFO - Starting attempt 1 of 1
[2023-03-27T02:09:35.084+0000] {taskinstance.py:1284} INFO - 
--------------------------------------------------------------------------------
[2023-03-27T02:09:35.112+0000] {taskinstance.py:1303} INFO - Executing <Task(PythonOperator): get_data_from_google_sheet> on 2023-03-27 02:09:32.849106+00:00
[2023-03-27T02:09:35.118+0000] {standard_task_runner.py:55} INFO - Started process 383 to run task
[2023-03-27T02:09:35.122+0000] {standard_task_runner.py:82} INFO - Running: ['***', 'tasks', 'run', 'dag_with_google_sheet_v01', 'get_data_from_google_sheet', 'manual__2023-03-27T02:09:32.849106+00:00', '--job-id', '324', '--raw', '--subdir', 'DAGS_FOLDER/dag_rw_google_sheet.py', '--cfg-path', '/tmp/tmpqv_u3woz']
[2023-03-27T02:09:35.126+0000] {standard_task_runner.py:83} INFO - Job 324: Subtask get_data_from_google_sheet
[2023-03-27T02:09:35.231+0000] {task_command.py:388} INFO - Running <TaskInstance: dag_with_google_sheet_v01.get_data_from_google_sheet manual__2023-03-27T02:09:32.849106+00:00 [running]> on host 703823a37821
[2023-03-27T02:09:35.345+0000] {taskinstance.py:1511} INFO - Exporting the following env vars:
AIRFLOW_CTX_DAG_OWNER=ThinhHuynh
AIRFLOW_CTX_DAG_ID=dag_with_google_sheet_v01
AIRFLOW_CTX_TASK_ID=get_data_from_google_sheet
AIRFLOW_CTX_EXECUTION_DATE=2023-03-27T02:09:32.849106+00:00
AIRFLOW_CTX_TRY_NUMBER=1
AIRFLOW_CTX_DAG_RUN_ID=manual__2023-03-27T02:09:32.849106+00:00
[2023-03-27T02:09:35.348+0000] {taskinstance.py:1775} ERROR - Task failed with exception
Traceback (most recent call last):
  File "/home/airflow/.local/lib/python3.7/site-packages/airflow/operators/python.py", line 175, in execute
    return_value = self.execute_callable()
  File "/home/airflow/.local/lib/python3.7/site-packages/airflow/operators/python.py", line 192, in execute_callable
    return self.python_callable(*self.op_args, **self.op_kwargs)
  File "/opt/airflow/dags/dag_rw_google_sheet.py", line 41, in insert_master
    dic = google_sheet.main()
  File "/opt/airflow/dags/google_sheet.py", line 39, in main
    'credentials.json', SCOPES)
  File "/home/airflow/.local/lib/python3.7/site-packages/google_auth_oauthlib/flow.py", line 204, in from_client_secrets_file
    with open(client_secrets_file, "r") as json_file:
FileNotFoundError: [Errno 2] No such file or directory: 'credentials.json'
[2023-03-27T02:09:35.368+0000] {taskinstance.py:1326} INFO - Marking task as FAILED. dag_id=dag_with_google_sheet_v01, task_id=get_data_from_google_sheet, execution_date=20230327T020932, start_date=20230327T020935, end_date=20230327T020935
[2023-03-27T02:09:35.386+0000] {standard_task_runner.py:105} ERROR - Failed to execute job 324 for task get_data_from_google_sheet ([Errno 2] No such file or directory: 'credentials.json'; 383)
[2023-03-27T02:09:35.415+0000] {local_task_job.py:212} INFO - Task exited with return code 1
[2023-03-27T02:09:35.434+0000] {taskinstance.py:2585} INFO - 0 downstream tasks scheduled from follow-on schedule check
