[2023-03-20T16:04:36.819+0000] {taskinstance.py:1084} INFO - Dependencies all met for dep_context=non-requeueable deps ti=<TaskInstance: dag_with_minio_s3_v01.sensor_minio_s3 manual__2023-03-20T16:04:14.815786+00:00 [queued]>
[2023-03-20T16:04:36.915+0000] {taskinstance.py:1084} INFO - Dependencies all met for dep_context=requeueable deps ti=<TaskInstance: dag_with_minio_s3_v01.sensor_minio_s3 manual__2023-03-20T16:04:14.815786+00:00 [queued]>
[2023-03-20T16:04:36.933+0000] {taskinstance.py:1282} INFO - 
--------------------------------------------------------------------------------
[2023-03-20T16:04:36.949+0000] {taskinstance.py:1283} INFO - Starting attempt 1 of 6
[2023-03-20T16:04:36.957+0000] {taskinstance.py:1284} INFO - 
--------------------------------------------------------------------------------
[2023-03-20T16:04:37.527+0000] {taskinstance.py:1303} INFO - Executing <Task(S3KeySensor): sensor_minio_s3> on 2023-03-20 16:04:14.815786+00:00
[2023-03-20T16:04:37.593+0000] {standard_task_runner.py:55} INFO - Started process 968 to run task
[2023-03-20T16:04:37.625+0000] {standard_task_runner.py:82} INFO - Running: ['***', 'tasks', 'run', 'dag_with_minio_s3_v01', 'sensor_minio_s3', 'manual__2023-03-20T16:04:14.815786+00:00', '--job-id', '91', '--raw', '--subdir', 'DAGS_FOLDER/dag_with_minio_s3.py', '--cfg-path', '/tmp/tmp73f6hjz8']
[2023-03-20T16:04:37.659+0000] {standard_task_runner.py:83} INFO - Job 91: Subtask sensor_minio_s3
[2023-03-20T16:04:38.234+0000] {task_command.py:388} INFO - Running <TaskInstance: dag_with_minio_s3_v01.sensor_minio_s3 manual__2023-03-20T16:04:14.815786+00:00 [running]> on host a1e5df821a6d
[2023-03-20T16:04:38.603+0000] {taskinstance.py:1511} INFO - Exporting the following env vars:
AIRFLOW_CTX_DAG_OWNER=ThinhHuynh
AIRFLOW_CTX_DAG_ID=dag_with_minio_s3_v01
AIRFLOW_CTX_TASK_ID=sensor_minio_s3
AIRFLOW_CTX_EXECUTION_DATE=2023-03-20T16:04:14.815786+00:00
AIRFLOW_CTX_TRY_NUMBER=1
AIRFLOW_CTX_DAG_RUN_ID=manual__2023-03-20T16:04:14.815786+00:00
[2023-03-20T16:04:38.605+0000] {s3.py:99} INFO - Poking for key : s3://***/data.csv
[2023-03-20T16:04:38.611+0000] {base_aws.py:133} INFO - No connection ID provided. Fallback on boto3 credential strategy (region_name=None). See: https://boto3.amazonaws.com/v1/documentation/api/latest/guide/configuration.html
[2023-03-20T16:04:41.933+0000] {taskinstance.py:1775} ERROR - Task failed with exception
Traceback (most recent call last):
  File "/home/airflow/.local/lib/python3.7/site-packages/airflow/sensors/base.py", line 199, in execute
    poke_return = self.poke(context)
  File "/home/airflow/.local/lib/python3.7/site-packages/airflow/providers/amazon/aws/sensors/s3.py", line 130, in poke
    return self._check_key(self.bucket_key)
  File "/home/airflow/.local/lib/python3.7/site-packages/airflow/providers/amazon/aws/sensors/s3.py", line 118, in _check_key
    obj = self.hook.head_object(key, bucket_name)
  File "/home/airflow/.local/lib/python3.7/site-packages/airflow/providers/amazon/aws/hooks/s3.py", line 111, in wrapper
    return func(*bound_args.args, **bound_args.kwargs)
  File "/home/airflow/.local/lib/python3.7/site-packages/airflow/providers/amazon/aws/hooks/s3.py", line 82, in wrapper
    return func(*bound_args.args, **bound_args.kwargs)
  File "/home/airflow/.local/lib/python3.7/site-packages/airflow/providers/amazon/aws/hooks/s3.py", line 499, in head_object
    return self.get_conn().head_object(Bucket=bucket_name, Key=key)
  File "/home/airflow/.local/lib/python3.7/site-packages/botocore/client.py", line 530, in _api_call
    return self._make_api_call(operation_name, kwargs)
  File "/home/airflow/.local/lib/python3.7/site-packages/botocore/client.py", line 944, in _make_api_call
    operation_model, request_dict, request_context
  File "/home/airflow/.local/lib/python3.7/site-packages/botocore/client.py", line 966, in _make_request
    return self._endpoint.make_request(operation_model, request_dict)
  File "/home/airflow/.local/lib/python3.7/site-packages/botocore/endpoint.py", line 119, in make_request
    return self._send_request(request_dict, operation_model)
  File "/home/airflow/.local/lib/python3.7/site-packages/botocore/endpoint.py", line 198, in _send_request
    request = self.create_request(request_dict, operation_model)
  File "/home/airflow/.local/lib/python3.7/site-packages/botocore/endpoint.py", line 137, in create_request
    operation_name=operation_model.name,
  File "/home/airflow/.local/lib/python3.7/site-packages/botocore/hooks.py", line 412, in emit
    return self._emitter.emit(aliased_event_name, **kwargs)
  File "/home/airflow/.local/lib/python3.7/site-packages/botocore/hooks.py", line 256, in emit
    return self._emit(event_name, kwargs)
  File "/home/airflow/.local/lib/python3.7/site-packages/botocore/hooks.py", line 239, in _emit
    response = handler(**kwargs)
  File "/home/airflow/.local/lib/python3.7/site-packages/botocore/signers.py", line 105, in handler
    return self.sign(operation_name, request)
  File "/home/airflow/.local/lib/python3.7/site-packages/botocore/signers.py", line 189, in sign
    auth.add_auth(request)
  File "/home/airflow/.local/lib/python3.7/site-packages/botocore/auth.py", line 418, in add_auth
    raise NoCredentialsError()
botocore.exceptions.NoCredentialsError: Unable to locate credentials
[2023-03-20T16:04:42.073+0000] {taskinstance.py:1326} INFO - Marking task as UP_FOR_RETRY. dag_id=dag_with_minio_s3_v01, task_id=sensor_minio_s3, execution_date=20230320T160414, start_date=20230320T160436, end_date=20230320T160442
[2023-03-20T16:04:44.713+0000] {standard_task_runner.py:105} ERROR - Failed to execute job 91 for task sensor_minio_s3 (Unable to locate credentials; 968)
[2023-03-20T16:04:44.880+0000] {local_task_job.py:212} INFO - Task exited with return code 1
[2023-03-20T16:04:45.334+0000] {taskinstance.py:2585} INFO - 0 downstream tasks scheduled from follow-on schedule check
